Workbook

Sheet BOQ
D1: QUOTATION
D4: Doc No. 文件号: | E4: QUO/PTJMTI/BBS/PRSG/4/26/R127
D5: Date日期: | E5: =NOW() -> 46206.708
D7: Payment Terms 付款条件:
D8: DP - 40% after signing contract
D9: 预付款 - 合同签署后支付 40%
A10: To: | B10: PT. JIANGYI MOLD TECHNOLOGY INDONESIA | D10: Payment 1: 30% after 60% work progress
B11: Bangsri Utara, Bangsri, Kec. Bulakamba, Kabupaten Brebes, | D11: 第一期付款：支付 30% 工程进度60%
B12: Jawa Tengah 52253 | D12: Payment 2: 25% after 100% work progress
A13: Attn: | D13: 第二期付款：支付 25%工程进度100%
A14: Tel: | D14: Retention: 5% after BAST
D15: 质保金：项目验收（BAST）后支付 5%
A16: Project项目: PEMBUATAN RUANG SELASAR GEDUNG PRODUKSI 生产车间连廊空间建设
A18: No. 号 | B18: Description 工作项目 | C18: Qty 数量 | D18: Unit 单位 | E18: Harga Satuan 单价 | F18: Jumlah Harga 总价 | G18: Brand Spek 品牌规格
E19: (Rp) | F19: (Rp)
A20: A | B20: PEKERJAAN PERSIAPAN 施工准备工作
A21: 1 | B21: Mob dan Demobilisasi 设备和人员的进出场 | C21: =VOL!W11 -> 1 | D21: =VOL!X11 -> ls | E21: 2000000 | F21: =C21*E21 -> 2000000
A22: 2 | B22: Alat Bantu Pekerjaan 施工辅助工具 | C22: =VOL!W12 -> 1 | D22: =VOL!X12 -> ls | E22: 1000000 | F22: =C22*E22 -> 1000000
A23: 3 | B23: Safety | C23: =VOL!W13 -> 1 | D23: =VOL!X13 -> ls | E23: 500000 | F23: =C23*E23 -> 500000
A24: 4 | B24: Cleaning 清理 | C24: =VOL!W14 -> 1 | D24: =VOL!X14 -> ls | E24: 500000 | F24: =C24*E24 -> 500000
A26: B | B26: RUANG SELASAR GEDUNG PRODUKSI (A & B) A栋及B栋生产车间走廊区域
A27: 1 | B27: Pekerjaan Partisi UPVC 隔断工程 | C27: =VOL!W17 -> 203.44275 | D27: =VOL!X17 -> m2 | E27: 410000 | F27: =C27*E27 -> 83411528
B28: Spek :
A29: - | B29: Partisi UPVC Single Layer 单层UPVC隔断 | G29: Alderon/Setara
A30: - | B30: Siku 50x50mm 角钢 | G30: KS/LS/Setara
A31: - | B31: CNP 100x50x2,3mm C型钢 | G31: KS/LS/Setara
A32: - | B32: Pengecatan Rangka Partisi 隔断骨架油漆施工 | G32: Ftalit - Kansai
A34: 2 | B34: Pekerjaan Cor Lantai 地面混凝土浇筑工程
B35: scoope :
A36: - | B36: Plastik Cor 混凝土保护塑料膜 | C36: =VOL!W34 -> 127.88315 | D36: =VOL!X34 -> m2 | E36: 4500 | F36: =C36*E36 -> 575474.18
A37: - | B37: Wiremesh M8, 2 Lapis 钢筋网片 | C37: =VOL!W39 -> 255.7663 | D37: =VOL!X39 -> m2 | E37: 107073.26 | F37: =C37*E37 -> 27385731 | G37: KS/LS/Setara
A38: - | B38: Bekisting 模板 | C38: =VOL!W41 -> 27.408 | D38: =VOL!X41 -> m2 | E38: 150000 | F38: =C38*E38 -> 4111200 | G38: Multipleks
A39: - | B39: Beton K-350 混凝土 | C39: =VOL!W45 -> 38.796945 | D39: =VOL!X45 -> m3 | E39: 1300000 | F39: =C39*E39 -> 50436028 | G39: Ready Mix
A41: 3 | B41: Pintu Double Swing uk. 2200x4000mm 双开门 | C41: =VOL!W49 -> 2 | D41: =VOL!X49 -> unit | E41: 9650000 | F41: =C41*E41 -> 19300000
B42: Spek :
A43: - | B43: Kusen Hollow 100x100x3mm 门框采用100x100x3mm方管 | G43: KS/LS/Setara
A44: - | B44: Siku 50x50x5mm 角钢 | G44: KS/LS/Setara
A45: - | B45: Partisi UPVC Single Layer 单层UPVC隔断 | G45: Alderon/Setara
A46: - | B46: Finishing Cat Besi 钢结构油漆饰面 | G46: Ftalit - Kansai
A47: - | B47: Aksesoris 门配件
...

Sheet VOL
B1: PT. MJK
B2: =BOQ!A16 -> Project项目: PEMBUATAN RUANG SELASAR GEDUNG PRODUKSI 生产车间连廊空间建设
B3: Back Up Volume
B6: No | C6: Uraian Pekerjaan | H6: Dia. | I6: Formation Of Bar Member | Q6: Dimensi | V6: n | W6: Volume | X6: Sat
I7: 1.5 | J7: 4 | K7: 6 | L7: 12 | M7: 15 | N7: 25 | O7: 40 | P7: 50 | Q7: Panjang | R7: Lebar | S7: tinggi | T7: Kg(m) | U7: qty
Q8: (m) | R8: (m) | S8: (m)
B10: =BOQ!A20 -> A | C10: =BOQ!B20 -> PEKERJAAN PERSIAPAN 施工准备工作
B11: =BOQ!A21 -> 1 | C11: =BOQ!B21 -> Mob dan Demobilisasi 设备和人员的进出场 | W11: 1 | X11: ls
B12: =BOQ!A22 -> 2 | C12: =BOQ!B22 -> Alat Bantu Pekerjaan 施工辅助工具 | W12: 1 | X12: ls
B13: =BOQ!A23 -> 3 | C13: =BOQ!B23 -> Safety | W13: 1 | X13: ls
B14: =BOQ!A24 -> 4 | C14: =BOQ!B24 -> Cleaning 清理 | W14: 1 | X14: ls
B15: =BOQ!A25 -> 0 | C15: =BOQ!B25 -> 0
B16: =BOQ!A26 -> B | C16: =BOQ!B26 -> RUANG SELASAR GEDUNG PRODUKSI (A & B) A栋及B栋生产车间走廊区域
B17: =BOQ!A27 -> 1 | C17: =BOQ!B27 -> Pekerjaan Partisi UPVC 隔断工程 | W17: =SUM(W23:W30) -> 203.44275 | X17: m2 | Y17: =W17*3% -> 6.1032825 | Z17: =W17-Y17 -> 197.33947
C18: =BOQ!B28 -> Spek :
B19: =BOQ!A29 -> - | C19: =BOQ!B29 -> Partisi UPVC Single Layer 单层UPVC隔断
B20: =BOQ!A30 -> - | C20: =BOQ!B30 -> Siku 50x50mm 角钢
B21: =BOQ!A31 -> - | C21: =BOQ!B31 -> CNP 100x50x2,3mm C型钢
B22: =BOQ!A32 -> - | C22: =BOQ!B32 -> Pengecatan Rangka Partisi 隔断骨架油漆施工
G23: gedung A | H23: tampak depan | Q23: 12.43 | S23: 4.825 | U23: 1 | W23: =Q23*S23*U23 -> 59.97475
H24: tampak samping | Q24: 5.18 | S24: =(5.275+4.825)/2 -> 5.05 | U24: 1 | W24: =Q24*S24*U24 -> 26.159
Q25: 5.23 | S25: =(5.275+4.825)/2 -> 5.05 | U25: 1 | W25: =Q25*S25*U25 -> 26.4115
G26: gedung B | H26: tampak depan | Q26: 12.5 | S26: 4.825 | U26: 1 | W26: =Q26*S26*U26 -> 60.3125
H27: tampak samping | Q27: 5.2 | S27: =(5.275+4.825)/2 -> 5.05 | U27: 1 | W27: =Q27*S27*U27 -> 26.26
Q28: 5.14 | S28: =(5.275+4.825)/2 -> 5.05 | U28: 1 | W28: =Q28*S28*U28 -> 25.957
H29: pengurangan pintu | Q29: 2.2 | S29: 4 | U29: =-W49 -> -2 | W29: =Q29*S29*U29 -> -17.6
H30: jendela | Q30: 1.44 | S30: 1.4 | U30: =-W57 -> -2 | W30: =Q30*S30*U30 -> -4.032
B32: =BOQ!A34 -> 2 | C32: =BOQ!B34 -> Pekerjaan Cor Lantai 地面混凝土浇筑工程
B33: =BOQ!A35 -> 0 | C33: =BOQ!B35 -> scoope :
B34: =BOQ!A36 -> - | C34: =BOQ!B36 -> Plastik Cor 混凝土保护塑料膜 | W34: =SUM(W35:W38) -> 127.88315 | X34: m2 | Y34: =W34*3% -> 3.8364945 | Z34: =W34-Y34 -> 124.04666
Q35: =Q23 -> 12.43 | S35: =(5.18+5.23)/2 -> 5.205 | U35: 1 | W35: =Q35*S35*U35 -> 64.69815
Q36: =Q26 -> 12.5 | S36: =(5.2+5.14)/2 -> 5.17 | U36: 1 | W36: =Q36*S36*U36 -> 64.625
H37: Tutup manhole | Q37: 0.6 | S37: 0.6 | U37: 2 | V37: -2 | W37: =Q37*S37*U37*V37 -> -1.44
B39: =BOQ!A37 -> - | C39: =BOQ!B37 -> Wiremesh M8, 2 Lapis 钢筋网片 | W39: =W34*2 -> 255.7663 | X39: m2 | Y39: =W39*3% -> 7.672989 | Z39: =W39-Y39 -> 248.09331
B41: =BOQ!A38 -> - | C41: =BOQ!B38 -> Bekisting 模板 | U41: 2 | W41: =SUM(W42:W44) -> 27.408 | X41: m2 | Y41: =W41*3% -> 0.82224 | Z41: =W41-Y41 -> 26.58576
Q42: =Q46+R46*2 -> 22.84 | S42: =S46 -> 0.3 | U42: 2 | W42: =Q42*S42*U42 -> 13.704
Q43: =Q47+R47*2 -> 22.84 | S43: =S42 -> 0.3 | U43: 2 | W43: =Q43*S43*U43 -> 13.704
B45: =BOQ!A39 -> - | C45: =BOQ!B39 -> Beton K-350 混凝土 | W45: =SUM(W46:W48) -> 38.796945 | X45: m3 | Y45: =W45*3% -> 1.1639083 | Z45: =W45-Y45 -> 37.633037
Q46: =Q35 -> 12.43 | R46: =S35 -> 5.205 | S46: 0.3 | U46: 1 | W46: =Q46*R46*S46*U46 -> 19.409445
Q47: =Q36 -> 12.5 | R47: =S36 -> 5.17 | S47: =S46 -> 0.3 | U47: 1 | W47: =Q47*R47*S47*U47 -> 19.3875
...
