Workbook

Sheet BOQ
D1: QUOTATION
D4: Doc No. 文件号: | E4: QUO/PTAFI/BBS/PFB/R12
D5: Date日期: | E5: =NOW() -> 46216.626
D7: Payment Terms 付款条件:
D8: DP - 50% after signing contract
D9: 预付款 - 合同签署后支付 50%
A10: To: | B10: PT. ADONIA FOOTWEAR INDONESIA | D10: Payment 1: 100% after 100% work progress
B11: Lebaksiu Kidul, Kec. Lebaksiu, Kabupaten Tegal, | D11: 第一期付款：支付 100% 工程进度100%
B12: Jawa Tengah 52461
A13: Attn:
A14: Tel:
A16: Project项目: PENAMBAHAN FAN BLOWER B9 B9新增排风机工程
A18: No. 号 | B18: Description 工作项目 | C18: Qty 数量 | D18: Unit 单位 | E18: Harga Satuan 单价 | F18: Jumlah Harga 总价 | G18: Brand Spek 品牌规格
E19: (Rp) | F19: (Rp)
A20: A | B20: PENAMBAHAN SALURAN FAN DAN LOUVER GEDUNG B9 B9楼新增风管及百叶工程
A21: 1 | B21: Industrial Fan 1380 x 1380mm 工业风机，尺寸1380x1380mm | C21: 11 | D21: unit台 | E21: 3800000 | F21: =E21*C21 -> 41800000
A22: 2 | B22: Pekerjaan Saluran Fan 风管工程
B23: Scoope :
A24: - | B24: Bobokan Dinding Louver uk.800 x 800 x thk 150mm 百叶窗墙体开孔 尺寸800 x 800 x 厚度 150 mm | C24: 22 | D24: unit台 | E24: 125100 | F24: =E24*C24 -> 2752200
A25: - | B25: Bobokan Dinding fan blower uk.1380 x 1380 x thk 150mm 鼓风机墙体开孔 尺寸 1380 x 1380 x 厚度 150 mm | C25: =C21 -> 11 | D25: unit台 | E25: 227500 | F25: =E25*C25 -> 2502500
A26: - | B26: perapihan Dinding louver uk. 800x800mm 百叶窗墙体修整 尺寸 800 x 800 mm | C26: =C24 -> 22 | D26: =D24 -> unit台 | E26: 800000 | F26: =E26*C26 -> 17600000
A27: - | B27: Perapihan Dinding fan blower uk. 1380x1380mm 鼓风机墙体修整 尺寸 1380 x 1380 mm | C27: =C25 -> 11 | D27: =D24 -> unit台 | E27: 1082000 | F27: =E27*C27 -> 11902000
A29: 3 | B29: Fleksibel Ducting Ø20" Ø20英寸软风管 | C29: 77 | D29: m 米 | E29: 500000 | F29: =E29*C29 -> 38500000
A30: 4 | B30: Tee Way Ø20" Ø20英寸三通 | C30: 11 | D30: pcs 个 | E30: 1370000 | F30: =E30*C30 -> 15070000
A32: 5 | B32: Louver uk. 800x800mm 百叶风口，尺寸800x800mm
B33: Spek 规格 :
A34: - | B34: CNP 100x50x1,6mm C型钢 | C34: 13 | D34: btg 条 | E34: 640000 | F34: =E34*C34 -> 8320000 | G34: KS/LS/setara 同等品牌
A35: - | B35: Plat Hitam uk. 1220x1440x thk 1mm 铁板 尺寸 1220x1440x厚度1 mm | C35: 41 | D35: lbr 张 | E35: 728150 | F35: =E35*C35 -> 29854150 | G35: KS/LS/setara 同等品牌
A37: - | B37: Finishing Cat Besi 钢结构油漆饰面
B38: Spek 规格 :
B39: Cat kansai 155 (1 pail) =25kg kansai 油漆 155 (1 桶) =25公斤 | C39: 3 | D39: pail 桶 | E39: 2850000 | F39: =E39*C39 -> 8550000 | G39: Ftalit/Kansai/setara
B40: thinner B (1 kaleng) = 20 ltr (B 油漆稀释剂 ) （1桶）= 20 升 | C40: 1 | D40: pail 桶 | E40: 380000 | F40: =E40*C40 -> 380000
A42: - | B42: Consumable, paku rivet, kawat las 消耗品, 拉铆钉, 焊条 | C42: 1 | D42: lot 批 | E42: 3000000 | F42: =E42*C42 -> 3000000
A44: 6 | B44: Jasa Fabrikasi & Instalasi 制作以及安装
B45: Waktu Pelaksanaan 20 hari kerja 施工工期20天工作日
B46: teknisi 1 orang , 3 helper) 技术员1人，辅助工3人
B47: teknisi 200rb/ hari 技术员200.000印尼盾/天 | C47: 15 | D47: Hari | E47: 200000 | F47: =E47*C47 -> 3000000
B48: 200,000x15hari= 3,000.000 200,000x15天= 3,000.000
B49: helper=150rb /hari 辅助工150.000/天 | C49: 20 | D49: Hari | E49: 450000 | F49: =E49*C49 -> 9000000
B50: 150,000x3x20hari= 9,000.000 150,000x3x20天= 9,000.000
...

Sheet BOQ1
H3: QUOTATION
A6: Jl. Cempaka 2 NC.1 No.1, Desa/Kelurahan Wanakerta, | G6: Doc No: | H6: QUO/PTAFI/BBS/PFB/R12
A7: Kec. Bungursari, Kab Purwakarta, Provinsi Jawa Barat, 41181 | G7: Date: | H7: =NOW() -> 46216.626
A8: Email: modernjayakonstruksi@gmail.com | G8: P.I.C:
A10: To: | B10: PT. ADONIA FOOTWEAR INDONESIA | G10: Payment terms: | H10: DP - 50% after signing contract.
B11: Lebaksiu Kidul, Kec. Lebaksiu, Kabupaten Tegal, | H11: Payment 1: 100% after 100% Completion of the Work.
B12: Jawa Tengah 52461
A13: Attn: | B13: -
A14: Tel: | B14: -
A16: Project | B16: Penambahan Fan Blower B9 B9新增排风机工程
A18: No. 号码 | B18: Description 工作项目 | F18: Qty 容量 | G18: Unit 单位 | H18: Harga Satuan 单价 | I18: Jumlah Harga 总价 | J18: Note 备注
H19: (Rp) | I19: (Rp)
A20: A | B20: PENAMBAHAN SALURAN FAN DAN LOUVER GEDUNG B9 B9楼新增风管及百叶工程
A21: 1 | B21: Industrial Fan 1380 x 1380mm 工业风机，尺寸1380x1380mm | F21: =cal!X12 -> 11 | G21: =cal!Y12 -> unit台 | H21: 7350000 | I21: =H21*F21 -> 80850000
A22: 2 | B22: Pekerjaan Saluran Fan 风管工程 | F22: =cal!X13 -> 22 | G22: =cal!Y13 -> unit | H22: 5300000 | I22: =H22*F22 -> 116600000
B23: Scoope :
B24: - | C24: Bobokan Dinding Existing 现有墙体开孔
B25: - | C25: Perapihan Dinding 墙面修复
B26: - | C26: Fleksibel Ducting Ø20" Ø20英寸软风管
B27: - | C27: Tee Way Ø20" Ø20英寸三通
B28: - | C28: Louver uk. 800x800mm 百叶风口，尺寸800x800mm
C29: Spek :
C30: - | D30: CNP 100x50x1,6mm C型钢
C31: - | D31: Plat Hitam 1mm 黑钢板
C32: - | D32: Finishing Cat Besi 钢结构油漆饰面
A34: B | B34: BIAYA PERSIAPAN DAN TRANSPORTASI 准备及运输费用 | F34: =cal!X31 -> 1 | G34: =cal!Y31 -> lot | H34: 8500000 | I34: =H34*F34 -> 8500000
B36: SUBTOTAL | I36: =SUM(I20:I35) -> 205950000
A37: Bank Account: | I37: Subtotal | J37: =I36 -> 205950000
A38: Bank BCA | I38: Discount
A39: No. Rek.: 460-447-4444
A40: PT Modern Jaya Konstruksi
I41: Grand Total | J41: =SUM(J37:J40) -> 205950000
A42: NOTE:
A43: 1. The price stated above included (eg: installation, material, transportation fees etc.) 以上所述价格已包括（例如：安装费、材料、运输费等）。
A44: 2. The price stated above not included PPN 11% and PPH 上述价格不包括11%的增值税和个人所得税。
A45: 3. The price stated in this quotation is prepared based on the blueprint provided / blueprint agreed by both parties. If there are any changes requested, a revised quotation will be made. 此报价所述价格是根据提供的蓝图/双方同意的蓝图编制的。如有任何更改请求，将制作修订报价。
A46: 4. The work will be carried out within a period of at least XX working days starting from the day we received deposit payment. 工作将在我们收到定金后至少XX个工作日内进行。
A47: 5. Pt. Modern Jaya Konstruksi does not take responsibility to any unforeseen circumstances that are out of our control such as weather, flood or fire, burglary, global pandemic and etc that caused the delays of the project. Modern Jaya Konstruksi公司对我们无法控制的任何不可预见的情况（如天气、洪水、火灾、盗窃、全球性大流行等）造成的项目延迟不承担责任。
A48: 6. In the event that the Client wishes to cancel the Work at any time after the acceptance of the quotation, the Client shall pay all actual and reasonable costs and expenses incurred by PT. Modern Jaya Konstruksi. 若客户在接受报价后任何时候希望取消工作，客户应支付PT. Modern Jaya Konstruksi公司实际合理发生的所有费用和支出。
A49: 7. Pt. Modern Jaya Konstruksi cannot be held responsible for any loss or damage to property, materials, or personal injuries to individuals caused by personal actions of the Client or any third parties before, during, or after the works of project being carried on or works of project that have been completed. Modern Jaya Konstruksi公司不对客户或任何第三方在工程进行中或工程完成后的个人行为造成的财产损失、材料损坏或个人受伤负责。
...

Sheet cal
B2: ='BOQ1'!B16 -> Penambahan Fan Blower B9 B9新增排风机工程
B3: Back Up Volume
B6: No | C6: Uraian Pekerjaan | I6: Dia. | J6: Formation Of Bar Member | R6: Dimensi | W6: n | X6: Volume | Y6: Sat
J7: 1.5 | K7: 4 | L7: 6 | M7: 12 | N7: 15 | O7: 25 | P7: 40 | Q7: 50 | R7: Panjang | S7: Lebar | T7: tinggi | U7: Kg(m) | V7: qty
R8: (m) | S8: (m) | T8: (m)
D10: 0
B11: ='BOQ1'!A20 -> A | C11: ='BOQ1'!B20 -> PENAMBAHAN SALURAN FAN DAN LOUVER GEDUNG B9 B9楼新增风管及百叶工程
B12: ='BOQ1'!A21 -> 1 | C12: ='BOQ1'!B21 -> Industrial Fan 1380 x 1380mm 工业风机，尺寸1380x1380mm | X12: 11 | Y12: unit台
B13: ='BOQ1'!A22 -> 2 | C13: ='BOQ1'!B22 -> Pekerjaan Saluran Fan 风管工程 | X13: 22 | Y13: unit
C14: ='BOQ1'!B23 -> Scoope :
C15: ='BOQ1'!B24 -> - | D15: ='BOQ1'!C24 -> Bobokan Dinding Existing 现有墙体开孔 | X15: =SUM(X16:X18) -> 35.0284 | Y15: m2 平方米
H16: fan blower | R16: 1.38 | S16: 1.38 | W16: 11 | X16: =R16*S16*W16 -> 20.9484
H17: louver | R17: 0.8 | S17: 0.8 | W17: 22 | X17: =R17*S17*W17 -> 14.08
C19: ='BOQ1'!B25 -> - | D19: ='BOQ1'!C25 -> Perapihan Dinding 墙面修复 | X19: =SUM(X20:X22) -> 131.12 | Y19: m 米
R20: =R16*2+S16*2 -> 5.52 | W20: =W16 -> 11 | X20: =R20*W20 -> 60.72
R21: =R17*2+S17*2 -> 3.2 | W21: =W17 -> 22 | X21: =R21*W21 -> 70.4
C23: ='BOQ1'!B26 -> - | D23: ='BOQ1'!C26 -> Fleksibel Ducting Ø20" Ø20英寸软风管 | R23: 3.5 | W23: =W21 -> 22 | X23: =R23*W23 -> 77 | Y23: m 米
C24: ='BOQ1'!B27 -> - | D24: ='BOQ1'!C27 -> Tee Way Ø20" Ø20英寸三通 | X24: =W20 -> 11 | Y24: pcs 个
C25: ='BOQ1'!B28 -> - | D25: ='BOQ1'!C28 -> Louver uk. 800x800mm 百叶风口，尺寸800x800mm | X25: =W21 -> 22 | Y25: unit台
C26: ='BOQ1'!B29 -> 0 | D26: ='BOQ1'!C29 -> Spek :
C27: ='BOQ1'!B30 -> 0 | D27: ='BOQ1'!C30 -> - | E27: ='BOQ1'!D30 -> CNP 100x50x1,6mm C型钢
C28: ='BOQ1'!B31 -> 0 | D28: ='BOQ1'!C31 -> - | E28: ='BOQ1'!D31 -> Plat Hitam 1mm 黑钢板
C29: ='BOQ1'!B32 -> 0 | D29: ='BOQ1'!C32 -> - | E29: ='BOQ1'!D32 -> Finishing Cat Besi 钢结构油漆饰面
B31: ='BOQ1'!A34 -> B | C31: ='BOQ1'!B34 -> BIAYA PERSIAPAN DAN TRANSPORTASI 准备及运输费用 | X31: 1 | Y31: lot

Sheet RAP 1
B1: Rencana Anggaran Pelaksanaan
B2: Owner | D2: PT Adonia Footwear Indonesia 1
B3: ='BOQ1'!B16 -> Penambahan Fan Blower B9 B9新增排风机工程
B5: No. | C5: Item Pkerjaan | J5: Vol. | K5: Sat. | L5: Material | N5: Labour | P5: Total
L6: Harga | M6: Jumlah | N6: Harga | O6: Jumlah
B8: ='BOQ1'!A20 -> A | C8: ='BOQ1'!B20 -> PENAMBAHAN SALURAN FAN DAN LOUVER GEDUNG B9 B9楼新增风管及百叶工程
B9: ='BOQ1'!A21 -> 1 | C9: ='BOQ1'!B21 -> Industrial Fan 1380 x 1380mm 工业风机，尺寸1380x1380mm | J9: ='BOQ1'!F21 -> 11 | K9: ='BOQ1'!G21 -> unit台 | L9: =4264550*1.1 -> 4691005 | M9: =J9*L9 -> 51601055 | N9: 750000 | O9: =J9*N9 -> 8250000 | R9: =SUM(O9,M9,) -> 59851055 | S9: =R9/J9 -> 5441005 | T9: =S9*1.35 -> 7345356.8
B10: ='BOQ1'!A22 -> 2 | C10: ='BOQ1'!B22 -> Pekerjaan Saluran Fan 风管工程 | J10: ='BOQ1'!F22 -> 22 | K10: ='BOQ1'!G22 -> unit
C11: ='BOQ1'!B23 -> Scoope :
C12: ='BOQ1'!B24 -> - | D12: ='BOQ1'!C24 -> Bobokan Dinding Existing 现有墙体开孔 | J12: =cal!X15 -> 35.0284 | K12: =cal!Y15 -> m2 平方米 | N12: 74000 | O12: =N12*J12 -> 2592101.6 | R12: =SUM(O12,M12,) -> 2592101.6 | S12: =R12/J12 -> 74000 | T12: =S12*1.35 -> 99900
C13: ='BOQ1'!B25 -> - | D13: ='BOQ1'!C25 -> Perapihan Dinding 墙面修复 | J13: =cal!X19 -> 131.12 | K13: =cal!Y19 -> m 米 | R13: =SUM(O13:O53,M13:M53,) -> 20933128 | S13: =R13/J13 -> 159648.63 | T13: =S13*1.38 -> 220315.1
D14: - | E14: Plester t= 2,5 cm (1:4) | J14: =J13 -> 131.12 | K14: =K13 -> m 米
E15: - | F15: Material
F16: - | G16: Semen @50 kg | J16: =J14*0.25 -> 32.78 | K16: zak | L16: 57000 | M16: =J16*L16 -> 1868460
F17: - | G17: Pasir Pasang | J17: =J14*0.025 -> 3.278 | K17: m3 | L17: 250000 | M17: =J17*L17 -> 819500
E19: - | F19: Upah
F20: - | G20: Jasa Borongan (mandor) | J20: =J14 -> 131.12 | K20: m2 | N20: 45000 | O20: =J20*N20 -> 5900400
E22: - | F22: Lain-lain
F23: - | G23: Overhead, Alat & Konsumabel | J23: 0.03 | K23: ls | L23: =SUM(M16:M22,O16:O22) -> 8588360 | M23: =J23*L23 -> 257650.8
D25: - | E25: Acian
E26: - | F26: Material
F27: - | G27: Semen @50 kg | J27: =J14*0.076 -> 9.96512 | K27: zak | L27: =L16 -> 57000 | M27: =J27*L27 -> 568011.84
E29: - | F29: Upah
F30: - | G30: Jasa Borongan (mandor) | J30: =J14 -> 131.12 | K30: m2 | N30: 45000 | O30: =J30*N30 -> 5900400
E32: - | F32: Lain-lain
F33: - | G33: Overhead, Alat & Konsumabel | J33: 0.03 | K33: ls | L33: =SUM(M26:M32,O26:O32) -> 6468411.8 | M33: =J33*L33 -> 194052.36
D35: - | E35: Cat Dasar
E36: - | F36: Material
F37: - | G37: Cat Dasar warna putih | J37: =J14/10 -> 13.112 | K37: ltr | L37: 50000 | M37: =J37*L37 -> 655600
E39: - | F39: Upah
F40: - | G40: Jasa Borongan (mandor) | J40: =J14 -> 131.12 | K40: m2 | N40: 13000 | O40: =J40*N40 -> 1704560
E42: - | F42: Lain-lain
F43: - | G43: Overhead, Alat & Konsumabel | J43: 0.03 | K43: ls | L43: =SUM(M37:M42,O37:O42) -> 2360160 | M43: =J43*L43 -> 70804.8
D45: - | E45: Cat Finish
E46: - | F46: Material
F47: - | G47: Cat Finish | J47: =J14/6 -> 21.853333 | K47: ltr | L47: 55000 | M47: =J47*L47 -> 1201933.3 | P47: Vinilex
E49: - | F49: Upah
F50: - | G50: Jasa Borongan (mandor) | J50: =J14 -> 131.12 | K50: m2 | N50: =N40 -> 13000 | O50: =J50*N50 -> 1704560
E52: - | F52: Lain-lain
F53: - | G53: Overhead, Alat & Konsumabel | J53: 0.03 | K53: ls | L53: =SUM(M47:M52,O47:O52) -> 2906493.3 | M53: =J53*L53 -> 87194.8
...
